[INFO][2020-08-11 10:46:34,087] [autoreload.py] [autoreload.run_with_reloader:597]-Watching for file changes with StatReloader
[ERROR][2020-08-11 10:46:38,678] [log.py] [log.log_response:222]-Internal Server Error: /
Traceback (most recent call last):
  File "/home/rajan/ishare/env/lib/python3.8/site-packages/django/core/cache/__init__.py", line 50, in _create_cache
    backend_cls = import_string(backend)
  File "/home/rajan/ishare/env/lib/python3.8/site-packages/django/utils/module_loading.py", line 17, in import_string
    module = import_module(module_path)
  File "/usr/lib/python3.8/importlib/__init__.py", line 127, in import_module
    return _bootstrap._gcd_import(name[level:], package, level)
  File "<frozen importlib._bootstrap>", line 1014, in _gcd_import
  File "<frozen importlib._bootstrap>", line 991, in _find_and_load
  File "<frozen importlib._bootstrap>", line 961, in _find_and_load_unlocked
  File "<frozen importlib._bootstrap>", line 219, in _call_with_frames_removed
  File "<frozen importlib._bootstrap>", line 1014, in _gcd_import
  File "<frozen importlib._bootstrap>", line 991, in _find_and_load
  File "<frozen importlib._bootstrap>", line 973, in _find_and_load_unlocked
ModuleNotFoundError: No module named 'django_redis'

During handling of the above exception, another exception occurred:

Traceback (most recent call last):
  File "/home/rajan/ishare/env/lib/python3.8/site-packages/django/core/handlers/exception.py", line 34, in inner
    response = get_response(request)
  File "/home/rajan/ishare/env/lib/python3.8/site-packages/django/utils/deprecation.py", line 93, in __call__
    response = self.process_request(request)
  File "/home/rajan/ishare/env/lib/python3.8/site-packages/django/contrib/sessions/middleware.py", line 20, in process_request
    request.session = self.SessionStore(session_key)
  File "/home/rajan/ishare/env/lib/python3.8/site-packages/django/contrib/sessions/backends/cache.py", line 17, in __init__
    self._cache = caches[settings.SESSION_CACHE_ALIAS]
  File "/home/rajan/ishare/env/lib/python3.8/site-packages/django/core/cache/__init__.py", line 79, in __getitem__
    cache = _create_cache(alias)
  File "/home/rajan/ishare/env/lib/python3.8/site-packages/django/core/cache/__init__.py", line 52, in _create_cache
    raise InvalidCacheBackendError(
django.core.cache.backends.base.InvalidCacheBackendError: Could not find backend 'django_redis.cache.RedisCache': No module named 'django_redis'
[ERROR][2020-08-11 10:46:38,683] [basehttp.py] [basehttp.log_message:154]-"GET / HTTP/1.1" 500 110565
[ERROR][2020-08-11 10:46:38,996] [log.py] [log.log_response:222]-Internal Server Error: /favicon.ico
Traceback (most recent call last):
  File "/home/rajan/ishare/env/lib/python3.8/site-packages/django/core/cache/__init__.py", line 50, in _create_cache
    backend_cls = import_string(backend)
  File "/home/rajan/ishare/env/lib/python3.8/site-packages/django/utils/module_loading.py", line 17, in import_string
    module = import_module(module_path)
  File "/usr/lib/python3.8/importlib/__init__.py", line 127, in import_module
    return _bootstrap._gcd_import(name[level:], package, level)
  File "<frozen importlib._bootstrap>", line 1014, in _gcd_import
  File "<frozen importlib._bootstrap>", line 991, in _find_and_load
  File "<frozen importlib._bootstrap>", line 961, in _find_and_load_unlocked
  File "<frozen importlib._bootstrap>", line 219, in _call_with_frames_removed
  File "<frozen importlib._bootstrap>", line 1014, in _gcd_import
  File "<frozen importlib._bootstrap>", line 991, in _find_and_load
  File "<frozen importlib._bootstrap>", line 973, in _find_and_load_unlocked
ModuleNotFoundError: No module named 'django_redis'

During handling of the above exception, another exception occurred:

Traceback (most recent call last):
  File "/home/rajan/ishare/env/lib/python3.8/site-packages/django/core/handlers/exception.py", line 34, in inner
    response = get_response(request)
  File "/home/rajan/ishare/env/lib/python3.8/site-packages/django/utils/deprecation.py", line 93, in __call__
    response = self.process_request(request)
  File "/home/rajan/ishare/env/lib/python3.8/site-packages/django/contrib/sessions/middleware.py", line 20, in process_request
    request.session = self.SessionStore(session_key)
  File "/home/rajan/ishare/env/lib/python3.8/site-packages/django/contrib/sessions/backends/cache.py", line 17, in __init__
    self._cache = caches[settings.SESSION_CACHE_ALIAS]
  File "/home/rajan/ishare/env/lib/python3.8/site-packages/django/core/cache/__init__.py", line 79, in __getitem__
    cache = _create_cache(alias)
  File "/home/rajan/ishare/env/lib/python3.8/site-packages/django/core/cache/__init__.py", line 52, in _create_cache
    raise InvalidCacheBackendError(
django.core.cache.backends.base.InvalidCacheBackendError: Could not find backend 'django_redis.cache.RedisCache': No module named 'django_redis'
[INFO][2020-08-11 10:47:25,606] [autoreload.py] [autoreload.run_with_reloader:597]-Watching for file changes with StatReloader
[ERROR][2020-08-11 10:47:30,330] [log.py] [log.log_response:222]-Internal Server Error: /
Traceback (most recent call last):
  File "/home/rajan/ishare/env/lib/python3.8/site-packages/django/core/cache/__init__.py", line 50, in _create_cache
    backend_cls = import_string(backend)
  File "/home/rajan/ishare/env/lib/python3.8/site-packages/django/utils/module_loading.py", line 17, in import_string
    module = import_module(module_path)
  File "/usr/lib/python3.8/importlib/__init__.py", line 127, in import_module
    return _bootstrap._gcd_import(name[level:], package, level)
  File "<frozen importlib._bootstrap>", line 1014, in _gcd_import
  File "<frozen importlib._bootstrap>", line 991, in _find_and_load
  File "<frozen importlib._bootstrap>", line 961, in _find_and_load_unlocked
  File "<frozen importlib._bootstrap>", line 219, in _call_with_frames_removed
  File "<frozen importlib._bootstrap>", line 1014, in _gcd_import
  File "<frozen importlib._bootstrap>", line 991, in _find_and_load
  File "<frozen importlib._bootstrap>", line 973, in _find_and_load_unlocked
ModuleNotFoundError: No module named 'django_redis'

During handling of the above exception, another exception occurred:

Traceback (most recent call last):
  File "/home/rajan/ishare/env/lib/python3.8/site-packages/django/core/handlers/exception.py", line 34, in inner
    response = get_response(request)
  File "/home/rajan/ishare/env/lib/python3.8/site-packages/django/utils/deprecation.py", line 93, in __call__
    response = self.process_request(request)
  File "/home/rajan/ishare/env/lib/python3.8/site-packages/django/contrib/sessions/middleware.py", line 20, in process_request
    request.session = self.SessionStore(session_key)
  File "/home/rajan/ishare/env/lib/python3.8/site-packages/django/contrib/sessions/backends/cache.py", line 17, in __init__
    self._cache = caches[settings.SESSION_CACHE_ALIAS]
  File "/home/rajan/ishare/env/lib/python3.8/site-packages/django/core/cache/__init__.py", line 79, in __getitem__
    cache = _create_cache(alias)
  File "/home/rajan/ishare/env/lib/python3.8/site-packages/django/core/cache/__init__.py", line 52, in _create_cache
    raise InvalidCacheBackendError(
django.core.cache.backends.base.InvalidCacheBackendError: Could not find backend 'django_redis.cache.RedisCache': No module named 'django_redis'
[ERROR][2020-08-11 10:47:30,331] [basehttp.py] [basehttp.log_message:154]-"GET / HTTP/1.1" 500 110700
[ERROR][2020-08-11 10:47:32,845] [log.py] [log.log_response:222]-Internal Server Error: /
Traceback (most recent call last):
  File "/home/rajan/ishare/env/lib/python3.8/site-packages/django/core/cache/__init__.py", line 50, in _create_cache
    backend_cls = import_string(backend)
  File "/home/rajan/ishare/env/lib/python3.8/site-packages/django/utils/module_loading.py", line 17, in import_string
    module = import_module(module_path)
  File "/usr/lib/python3.8/importlib/__init__.py", line 127, in import_module
    return _bootstrap._gcd_import(name[level:], package, level)
  File "<frozen importlib._bootstrap>", line 1014, in _gcd_import
  File "<frozen importlib._bootstrap>", line 991, in _find_and_load
  File "<frozen importlib._bootstrap>", line 961, in _find_and_load_unlocked
  File "<frozen importlib._bootstrap>", line 219, in _call_with_frames_removed
  File "<frozen importlib._bootstrap>", line 1014, in _gcd_import
  File "<frozen importlib._bootstrap>", line 991, in _find_and_load
  File "<frozen importlib._bootstrap>", line 973, in _find_and_load_unlocked
ModuleNotFoundError: No module named 'django_redis'

During handling of the above exception, another exception occurred:

Traceback (most recent call last):
  File "/home/rajan/ishare/env/lib/python3.8/site-packages/django/core/handlers/exception.py", line 34, in inner
    response = get_response(request)
  File "/home/rajan/ishare/env/lib/python3.8/site-packages/django/utils/deprecation.py", line 93, in __call__
    response = self.process_request(request)
  File "/home/rajan/ishare/env/lib/python3.8/site-packages/django/contrib/sessions/middleware.py", line 20, in process_request
    request.session = self.SessionStore(session_key)
  File "/home/rajan/ishare/env/lib/python3.8/site-packages/django/contrib/sessions/backends/cache.py", line 17, in __init__
    self._cache = caches[settings.SESSION_CACHE_ALIAS]
  File "/home/rajan/ishare/env/lib/python3.8/site-packages/django/core/cache/__init__.py", line 79, in __getitem__
    cache = _create_cache(alias)
  File "/home/rajan/ishare/env/lib/python3.8/site-packages/django/core/cache/__init__.py", line 52, in _create_cache
    raise InvalidCacheBackendError(
django.core.cache.backends.base.InvalidCacheBackendError: Could not find backend 'django_redis.cache.RedisCache': No module named 'django_redis'
[ERROR][2020-08-11 10:47:32,846] [basehttp.py] [basehttp.log_message:154]-"GET / HTTP/1.1" 500 110700
[ERROR][2020-08-11 10:47:48,804] [log.py] [log.log_response:222]-Internal Server Error: /
Traceback (most recent call last):
  File "/home/rajan/ishare/env/lib/python3.8/site-packages/django/core/cache/__init__.py", line 50, in _create_cache
    backend_cls = import_string(backend)
  File "/home/rajan/ishare/env/lib/python3.8/site-packages/django/utils/module_loading.py", line 17, in import_string
    module = import_module(module_path)
  File "/usr/lib/python3.8/importlib/__init__.py", line 127, in import_module
    return _bootstrap._gcd_import(name[level:], package, level)
  File "<frozen importlib._bootstrap>", line 1014, in _gcd_import
  File "<frozen importlib._bootstrap>", line 991, in _find_and_load
  File "<frozen importlib._bootstrap>", line 961, in _find_and_load_unlocked
  File "<frozen importlib._bootstrap>", line 219, in _call_with_frames_removed
  File "<frozen importlib._bootstrap>", line 1014, in _gcd_import
  File "<frozen importlib._bootstrap>", line 991, in _find_and_load
  File "<frozen importlib._bootstrap>", line 973, in _find_and_load_unlocked
ModuleNotFoundError: No module named 'django_redis'

During handling of the above exception, another exception occurred:

Traceback (most recent call last):
  File "/home/rajan/ishare/env/lib/python3.8/site-packages/django/core/handlers/exception.py", line 34, in inner
    response = get_response(request)
  File "/home/rajan/ishare/env/lib/python3.8/site-packages/django/utils/deprecation.py", line 93, in __call__
    response = self.process_request(request)
  File "/home/rajan/ishare/env/lib/python3.8/site-packages/django/contrib/sessions/middleware.py", line 20, in process_request
    request.session = self.SessionStore(session_key)
  File "/home/rajan/ishare/env/lib/python3.8/site-packages/django/contrib/sessions/backends/cache.py", line 17, in __init__
    self._cache = caches[settings.SESSION_CACHE_ALIAS]
  File "/home/rajan/ishare/env/lib/python3.8/site-packages/django/core/cache/__init__.py", line 79, in __getitem__
    cache = _create_cache(alias)
  File "/home/rajan/ishare/env/lib/python3.8/site-packages/django/core/cache/__init__.py", line 52, in _create_cache
    raise InvalidCacheBackendError(
django.core.cache.backends.base.InvalidCacheBackendError: Could not find backend 'django_redis.cache.RedisCache': No module named 'django_redis'
[ERROR][2020-08-11 10:47:48,805] [basehttp.py] [basehttp.log_message:154]-"GET / HTTP/1.1" 500 110700
[INFO][2020-08-11 10:48:39,726] [autoreload.py] [autoreload.run_with_reloader:597]-Watching for file changes with StatReloader
[ERROR][2020-08-11 10:48:48,614] [log.py] [log.log_response:222]-Internal Server Error: /
Traceback (most recent call last):
  File "/home/rajan/ishare/env/lib/python3.8/site-packages/django/core/cache/__init__.py", line 50, in _create_cache
    backend_cls = import_string(backend)
  File "/home/rajan/ishare/env/lib/python3.8/site-packages/django/utils/module_loading.py", line 17, in import_string
    module = import_module(module_path)
  File "/usr/lib/python3.8/importlib/__init__.py", line 127, in import_module
    return _bootstrap._gcd_import(name[level:], package, level)
  File "<frozen importlib._bootstrap>", line 1014, in _gcd_import
  File "<frozen importlib._bootstrap>", line 991, in _find_and_load
  File "<frozen importlib._bootstrap>", line 961, in _find_and_load_unlocked
  File "<frozen importlib._bootstrap>", line 219, in _call_with_frames_removed
  File "<frozen importlib._bootstrap>", line 1014, in _gcd_import
  File "<frozen importlib._bootstrap>", line 991, in _find_and_load
  File "<frozen importlib._bootstrap>", line 973, in _find_and_load_unlocked
ModuleNotFoundError: No module named 'django_redis'

During handling of the above exception, another exception occurred:

Traceback (most recent call last):
  File "/home/rajan/ishare/env/lib/python3.8/site-packages/django/core/handlers/exception.py", line 34, in inner
    response = get_response(request)
  File "/home/rajan/ishare/env/lib/python3.8/site-packages/django/utils/deprecation.py", line 93, in __call__
    response = self.process_request(request)
  File "/home/rajan/ishare/env/lib/python3.8/site-packages/django/contrib/sessions/middleware.py", line 20, in process_request
    request.session = self.SessionStore(session_key)
  File "/home/rajan/ishare/env/lib/python3.8/site-packages/django/contrib/sessions/backends/cache.py", line 17, in __init__
    self._cache = caches[settings.SESSION_CACHE_ALIAS]
  File "/home/rajan/ishare/env/lib/python3.8/site-packages/django/core/cache/__init__.py", line 79, in __getitem__
    cache = _create_cache(alias)
  File "/home/rajan/ishare/env/lib/python3.8/site-packages/django/core/cache/__init__.py", line 52, in _create_cache
    raise InvalidCacheBackendError(
django.core.cache.backends.base.InvalidCacheBackendError: Could not find backend 'django_redis.cache.RedisCache': No module named 'django_redis'
[ERROR][2020-08-11 10:48:48,615] [basehttp.py] [basehttp.log_message:154]-"GET / HTTP/1.1" 500 110700
[ERROR][2020-08-11 10:48:52,498] [log.py] [log.log_response:222]-Internal Server Error: /admin/
Traceback (most recent call last):
  File "/home/rajan/ishare/env/lib/python3.8/site-packages/django/core/cache/__init__.py", line 50, in _create_cache
    backend_cls = import_string(backend)
  File "/home/rajan/ishare/env/lib/python3.8/site-packages/django/utils/module_loading.py", line 17, in import_string
    module = import_module(module_path)
  File "/usr/lib/python3.8/importlib/__init__.py", line 127, in import_module
    return _bootstrap._gcd_import(name[level:], package, level)
  File "<frozen importlib._bootstrap>", line 1014, in _gcd_import
  File "<frozen importlib._bootstrap>", line 991, in _find_and_load
  File "<frozen importlib._bootstrap>", line 961, in _find_and_load_unlocked
  File "<frozen importlib._bootstrap>", line 219, in _call_with_frames_removed
  File "<frozen importlib._bootstrap>", line 1014, in _gcd_import
  File "<frozen importlib._bootstrap>", line 991, in _find_and_load
  File "<frozen importlib._bootstrap>", line 973, in _find_and_load_unlocked
ModuleNotFoundError: No module named 'django_redis'

During handling of the above exception, another exception occurred:

Traceback (most recent call last):
  File "/home/rajan/ishare/env/lib/python3.8/site-packages/django/core/handlers/exception.py", line 34, in inner
    response = get_response(request)
  File "/home/rajan/ishare/env/lib/python3.8/site-packages/django/utils/deprecation.py", line 93, in __call__
    response = self.process_request(request)
  File "/home/rajan/ishare/env/lib/python3.8/site-packages/django/contrib/sessions/middleware.py", line 20, in process_request
    request.session = self.SessionStore(session_key)
  File "/home/rajan/ishare/env/lib/python3.8/site-packages/django/contrib/sessions/backends/cache.py", line 17, in __init__
    self._cache = caches[settings.SESSION_CACHE_ALIAS]
  File "/home/rajan/ishare/env/lib/python3.8/site-packages/django/core/cache/__init__.py", line 79, in __getitem__
    cache = _create_cache(alias)
  File "/home/rajan/ishare/env/lib/python3.8/site-packages/django/core/cache/__init__.py", line 52, in _create_cache
    raise InvalidCacheBackendError(
django.core.cache.backends.base.InvalidCacheBackendError: Could not find backend 'django_redis.cache.RedisCache': No module named 'django_redis'
[ERROR][2020-08-11 10:48:52,499] [basehttp.py] [basehttp.log_message:154]-"GET /admin/ HTTP/1.1" 500 110625
[INFO][2020-08-11 10:50:44,136] [autoreload.py] [autoreload.run_with_reloader:597]-Watching for file changes with StatReloader
[ERROR][2020-08-11 10:50:46,892] [log.py] [log.log_response:222]-Internal Server Error: /admin/
Traceback (most recent call last):
  File "/home/rajan/ishare/env/lib/python3.8/site-packages/django/core/cache/__init__.py", line 50, in _create_cache
    backend_cls = import_string(backend)
  File "/home/rajan/ishare/env/lib/python3.8/site-packages/django/utils/module_loading.py", line 17, in import_string
    module = import_module(module_path)
  File "/usr/lib/python3.8/importlib/__init__.py", line 127, in import_module
    return _bootstrap._gcd_import(name[level:], package, level)
  File "<frozen importlib._bootstrap>", line 1014, in _gcd_import
  File "<frozen importlib._bootstrap>", line 991, in _find_and_load
  File "<frozen importlib._bootstrap>", line 961, in _find_and_load_unlocked
  File "<frozen importlib._bootstrap>", line 219, in _call_with_frames_removed
  File "<frozen importlib._bootstrap>", line 1014, in _gcd_import
  File "<frozen importlib._bootstrap>", line 991, in _find_and_load
  File "<frozen importlib._bootstrap>", line 973, in _find_and_load_unlocked
ModuleNotFoundError: No module named 'django_redis'

During handling of the above exception, another exception occurred:

Traceback (most recent call last):
  File "/home/rajan/ishare/env/lib/python3.8/site-packages/django/core/handlers/exception.py", line 34, in inner
    response = get_response(request)
  File "/home/rajan/ishare/env/lib/python3.8/site-packages/django/utils/deprecation.py", line 93, in __call__
    response = self.process_request(request)
  File "/home/rajan/ishare/env/lib/python3.8/site-packages/django/contrib/sessions/middleware.py", line 20, in process_request
    request.session = self.SessionStore(session_key)
  File "/home/rajan/ishare/env/lib/python3.8/site-packages/django/contrib/sessions/backends/cache.py", line 17, in __init__
    self._cache = caches[settings.SESSION_CACHE_ALIAS]
  File "/home/rajan/ishare/env/lib/python3.8/site-packages/django/core/cache/__init__.py", line 79, in __getitem__
    cache = _create_cache(alias)
  File "/home/rajan/ishare/env/lib/python3.8/site-packages/django/core/cache/__init__.py", line 52, in _create_cache
    raise InvalidCacheBackendError(
django.core.cache.backends.base.InvalidCacheBackendError: Could not find backend 'django_redis.cache.RedisCache': No module named 'django_redis'
[ERROR][2020-08-11 10:50:46,893] [basehttp.py] [basehttp.log_message:154]-"GET /admin/ HTTP/1.1" 500 110773
[INFO][2020-08-11 10:51:11,111] [autoreload.py] [autoreload.run_with_reloader:597]-Watching for file changes with StatReloader
[INFO][2020-08-11 10:51:13,535] [basehttp.py] [basehttp.log_message:154]-"GET /admin/ HTTP/1.1" 302 0
[ERROR][2020-08-11 10:51:15,771] [log.py] [log.log_response:222]-Internal Server Error: /admin/login/
Traceback (most recent call last):
  File "/home/rajan/ishare/env/lib/python3.8/site-packages/django/core/handlers/exception.py", line 34, in inner
    response = get_response(request)
  File "/home/rajan/ishare/env/lib/python3.8/site-packages/django/utils/deprecation.py", line 96, in __call__
    response = self.process_response(request, response)
  File "/home/rajan/ishare/env/lib/python3.8/site-packages/django/contrib/sessions/middleware.py", line 58, in process_response
    request.session.save()
  File "/home/rajan/ishare/env/lib/python3.8/site-packages/django/contrib/sessions/backends/cache.py", line 56, in save
    return self.create()
  File "/home/rajan/ishare/env/lib/python3.8/site-packages/django/contrib/sessions/backends/cache.py", line 50, in create
    raise RuntimeError(
RuntimeError: Unable to create a new session key. It is likely that the cache is unavailable.
[ERROR][2020-08-11 10:51:15,772] [basehttp.py] [basehttp.log_message:154]-"GET /admin/login/?next=/admin/ HTTP/1.1" 500 81071
[INFO][2020-08-11 10:51:25,859] [basehttp.py] [basehttp.log_message:154]-"GET / HTTP/1.1" 200 7496
[INFO][2020-08-11 10:51:25,885] [basehttp.py] [basehttp.log_message:154]-"GET /static/layer/mobile/need/layer.css HTTP/1.1" 200 5260
[INFO][2020-08-11 10:51:25,886] [basehttp.py] [basehttp.log_message:154]-"GET /static/css/base.css HTTP/1.1" 200 32534
[INFO][2020-08-11 10:51:25,887] [basehttp.py] [basehttp.log_message:154]-"GET /static/css/m.css HTTP/1.1" 200 5388
[INFO][2020-08-11 10:51:25,893] [basehttp.py] [basehttp.log_message:154]-"GET /static/js/comm.js HTTP/1.1" 200 7817
[INFO][2020-08-11 10:51:25,893] [basehttp.py] [basehttp.log_message:154]-"GET /static/layer/layer.js HTTP/1.1" 200 22116
[INFO][2020-08-11 10:51:25,894] [basehttp.py] [basehttp.log_message:154]-"GET /static/js/egg.js HTTP/1.1" 200 3128
[INFO][2020-08-11 10:51:25,904] [basehttp.py] [basehttp.log_message:154]-"GET /static/image/sale.png HTTP/1.1" 200 5870
[INFO][2020-08-11 10:51:25,905] [basehttp.py] [basehttp.log_message:154]-"GET /static/image/notice.png HTTP/1.1" 200 5601
[INFO][2020-08-11 10:51:25,906] [basehttp.py] [basehttp.log_message:154]-"GET /static/image/srwx.jpg HTTP/1.1" 200 24188
[INFO][2020-08-11 10:51:25,907] [basehttp.py] [basehttp.log_message:154]-"GET /static/image/wxgzh.jpg HTTP/1.1" 200 28008
[INFO][2020-08-11 10:51:25,977] [basehttp.py] [basehttp.log_message:154]-"GET /static/js/jquery-1.8.3.min.js HTTP/1.1" 200 95355
[INFO][2020-08-11 10:51:26,046] [basehttp.py] [basehttp.log_message:154]-"GET /static/layer/theme/default/layer.css?v=3.1.1 HTTP/1.1" 200 14367
[INFO][2020-08-11 10:51:26,055] [basehttp.py] [basehttp.log_message:154]-"GET /static/image/left.png HTTP/1.1" 200 1234
[INFO][2020-08-11 10:51:26,056] [basehttp.py] [basehttp.log_message:154]-"GET /static/image/right.png HTTP/1.1" 200 1233
[INFO][2020-08-11 10:51:26,057] [basehttp.py] [basehttp.log_message:154]-"GET /static/image/close.png HTTP/1.1" 200 1440
[INFO][2020-08-11 10:51:26,057] [basehttp.py] [basehttp.log_message:154]-"GET /static/image/jt.png HTTP/1.1" 200 173
[INFO][2020-08-11 10:51:26,058] [basehttp.py] [basehttp.log_message:154]-"GET /static/image/bg.png HTTP/1.1" 200 1290
[INFO][2020-08-11 10:51:26,061] [basehttp.py] [basehttp.log_message:154]-"GET /static/image/top.png HTTP/1.1" 200 1272
[INFO][2020-08-11 10:51:26,155] [basehttp.py] [basehttp.log_message:154]-"GET /static/image/favicon.ico HTTP/1.1" 200 16958
[INFO][2020-08-11 10:51:26,195] [basehttp.py] [basehttp.log_message:154]-"GET /static/layer/theme/default/loading-1.gif HTTP/1.1" 200 701
[INFO][2020-08-11 10:52:37,891] [autoreload.py] [autoreload.run_with_reloader:597]-Watching for file changes with StatReloader
[INFO][2020-08-11 10:52:54,351] [autoreload.py] [autoreload.run_with_reloader:597]-Watching for file changes with StatReloader
[INFO][2020-08-11 10:52:56,811] [basehttp.py] [basehttp.log_message:154]-"GET / HTTP/1.1" 200 7496
[INFO][2020-08-11 10:52:56,835] [basehttp.py] [basehttp.log_message:154]-"GET /static/js/comm.js HTTP/1.1" 304 0
[INFO][2020-08-11 10:52:56,835] [basehttp.py] [basehttp.log_message:154]-"GET /static/layer/layer.js HTTP/1.1" 304 0
[INFO][2020-08-11 10:52:56,836] [basehttp.py] [basehttp.log_message:154]-"GET /static/js/jquery-1.8.3.min.js HTTP/1.1" 304 0
[INFO][2020-08-11 10:52:56,836] [basehttp.py] [basehttp.log_message:154]-"GET /static/js/egg.js HTTP/1.1" 304 0
[INFO][2020-08-11 10:52:56,865] [basehttp.py] [basehttp.log_message:154]-"GET /static/js/jquery-1.8.3.min.js HTTP/1.1" 304 0
[INFO][2020-08-11 10:52:56,888] [basehttp.py] [basehttp.log_message:154]-"GET /static/image/sale.png HTTP/1.1" 304 0
[INFO][2020-08-11 10:52:56,888] [basehttp.py] [basehttp.log_message:154]-"GET /static/image/srwx.jpg HTTP/1.1" 304 0
[INFO][2020-08-11 10:52:56,889] [basehttp.py] [basehttp.log_message:154]-"GET /static/image/notice.png HTTP/1.1" 304 0
[INFO][2020-08-11 10:52:56,890] [basehttp.py] [basehttp.log_message:154]-"GET /static/image/wxgzh.jpg HTTP/1.1" 304 0
[INFO][2020-08-11 10:53:00,499] [basehttp.py] [basehttp.log_message:154]-"GET /admin/ HTTP/1.1" 302 0
[ERROR][2020-08-11 10:53:02,997] [log.py] [log.log_response:222]-Internal Server Error: /admin/login/
Traceback (most recent call last):
  File "/home/rajan/ishare/env/lib/python3.8/site-packages/django/core/handlers/exception.py", line 34, in inner
    response = get_response(request)
  File "/home/rajan/ishare/env/lib/python3.8/site-packages/django/utils/deprecation.py", line 96, in __call__
    response = self.process_response(request, response)
  File "/home/rajan/ishare/env/lib/python3.8/site-packages/django/contrib/sessions/middleware.py", line 58, in process_response
    request.session.save()
  File "/home/rajan/ishare/env/lib/python3.8/site-packages/django/contrib/sessions/backends/cache.py", line 56, in save
    return self.create()
  File "/home/rajan/ishare/env/lib/python3.8/site-packages/django/contrib/sessions/backends/cache.py", line 50, in create
    raise RuntimeError(
RuntimeError: Unable to create a new session key. It is likely that the cache is unavailable.
[ERROR][2020-08-11 10:53:02,997] [basehttp.py] [basehttp.log_message:154]-"GET /admin/login/?next=/admin/ HTTP/1.1" 500 81070
[INFO][2020-08-11 10:55:26,968] [autoreload.py] [autoreload.run_with_reloader:597]-Watching for file changes with StatReloader
[ERROR][2020-08-11 10:55:35,506] [log.py] [log.log_response:222]-Internal Server Error: /admin/login/
Traceback (most recent call last):
  File "/home/rajan/ishare/env/lib/python3.8/site-packages/django/core/handlers/exception.py", line 34, in inner
    response = get_response(request)
  File "/home/rajan/ishare/env/lib/python3.8/site-packages/django/utils/deprecation.py", line 96, in __call__
    response = self.process_response(request, response)
  File "/home/rajan/ishare/env/lib/python3.8/site-packages/django/contrib/sessions/middleware.py", line 58, in process_response
    request.session.save()
  File "/home/rajan/ishare/env/lib/python3.8/site-packages/django/contrib/sessions/backends/cache.py", line 56, in save
    return self.create()
  File "/home/rajan/ishare/env/lib/python3.8/site-packages/django/contrib/sessions/backends/cache.py", line 50, in create
    raise RuntimeError(
RuntimeError: Unable to create a new session key. It is likely that the cache is unavailable.
[ERROR][2020-08-11 10:55:35,507] [basehttp.py] [basehttp.log_message:154]-"GET /admin/login/?next=/admin/ HTTP/1.1" 500 81206
